Workbook

Sheet RAW_SKU_DATA
A1: SKU | B1: STT | C1: Campaign Name | D1: Loại Campaign | E1: Target | F1: Ghi chú | G1: Status | H1: Impressions | I1: Clicks | J1: Click-through Rate | K1: Spend | L1: Sales | M1: Orders | N1: Units | O1: Conversion Rate | P1: ACOS | Q1: CPC | R1: ROAS | ZZ1: SKU_LIST
A2: MOTHERDAY_ILOVEYOUMOM | B2: 1 | C2: MOTHERDAY_ILOVEYOUMOM_KT_ALLSG | D2: Keyword (Từ khóa) | E2: 100 reasons why i love you jar | F2: [[Broad]-[0.35]-[0T-0R-0P]] | G2: Enable | H2: 4 | I2: 0 | J2: 0 | K2: 0 | L2: 0 | M2: 0 | N2: 0 | O2: 0 | P2: 0 | Q2: 0 | R2: 0 | ZZ2: B2-WBSR-5J3P
A3: MOTHERDAY_ILOVEYOUMOM | B3: 2 | C3: MOTHERDAY_ILOVEYOUMOM_KT_ALLSG | D3: Keyword (Từ khóa) | E3: birthday gift | F3: [[Phrase]-[0.35]-[0T-0R-0P]] | G3: Enable | H3: 13 | I3: 0 | J3: 0 | K3: 0 | L3: 0 | M3: 0 | N3: 0 | O3: 0 | P3: 0 | Q3: 0 | R3: 0 | ZZ3: BIBLEJAR_CHRISTMARS_GAP
A4: MOTHERDAY_ILOVEYOUMOM | B4: 3 | C4: MOTHERDAY_ILOVEYOUMOM_KT_ALLSG | D4: Keyword (Từ khóa) | E4: birthday gift | F4: [[Broad]-[0.35]-[0T-0R-0P]] | G4: Enable | H4: 464 | I4: 0 | J4: 0 | K4: 0 | L4: 0 | M4: 0 | N4: 0 | O4: 0 | P4: 0 | Q4: 0 | R4: 0 | ZZ4: BIBLEJAR_DAD2026
A5: MOTHERDAY_ILOVEYOUMOM | B5: 4 | C5: MOTHERDAY_ILOVEYOUMOM_KT_motherday | D5: Keyword (Từ khóa) | E5: birthday gift mom | F5: [[Phrase]-[0.56]-[20T-20R-20P]] | G5: Enable | H5: 40 | I5: 0 | J5: 0 | K5: 0 | L5: 0 | M5: 0 | N5: 0 | O5: 0 | P5: 0 | Q5: 0 | R5: 0 | ZZ5: BIBLEJAR_MOM
A6: MOTHERDAY_ILOVEYOUMOM | B6: 5 | C6: MOTHERDAY_ILOVEYOUMOM_KT_ALLSG | D6: Keyword (Từ khóa) | E6: birthday gift mom | F6: [[Broad]-[0.35]-[0T-0R-0P]] | G6: Enable | H6: 248 | I6: 3 | J6: 0.0121 | K6: 0.84 | L6: 0 | M6: 0 | N6: 0 | O6: 0 | P6: 0 | Q6: 0.28 | R6: 0 | ZZ6: BIBLEJAR_MOM2026
A7: MOTHERDAY_ILOVEYOUMOM | B7: 6 | C7: MOTHERDAY_ILOVEYOUMOM_KT_motherday | D7: Keyword (Từ khóa) | E7: daughter gift from mom | F7: [[Exact]-[0.56]-[20T-20R-20P]] | G7: Enable | H7: 132 | I7: 0 | J7: 0 | K7: 0 | L7: 0 | M7: 0 | N7: 0 | O7: 0 | P7: 0 | Q7: 0 | R7: 0 | ZZ7: BRACELET_BLACK
A8: MOTHERDAY_ILOVEYOUMOM | B8: 7 | C8: MOTHERDAY_ILOVEYOUMOM_KT_ALLSG | D8: Keyword (Từ khóa) | E8: daughter gift from mom | F8: [[Broad]-[0.35]-[0T-0R-0P]] | G8: Enable | H8: 183 | I8: 3 | J8: 0.0164 | K8: 0.96 | L8: 0 | M8: 0 | N8: 0 | O8: 0 | P8: 0 | Q8: 0.32 | R8: 0 | ZZ8: BRACELET_PINK
A9: MOTHERDAY_ILOVEYOUMOM | B9: 8 | C9: MOTHERDAY_ILOVEYOUMOM_KT_35TRP_Exact_diy gifts for mom | D9: Keyword (Từ khóa) | E9: diy gifts for mom | F9: [[Exact]-[0.6]-[35T-35R-35P]] | G9: Enable | H9: 33 | I9: 1 | J9: 0.0303 | K9: 0.13 | L9: 0 | M9: 0 | N9: 0 | O9: 0 | P9: 0 | Q9: 0.13 | R9: 0 | ZZ9: CARD_HEART_MOM_01
A10: MOTHERDAY_ILOVEYOUMOM | B10: 9 | C10: MOTHERDAY_ILOVEYOUMOM_KT_35TRP_phrase_diy gifts for mom | D10: Keyword (Từ khóa) | E10: diy gifts for mom | F10: [[Phrase]-[0.6]-[35T-35R-35P]] | G10: Enable | H10: 25 | I10: 1 | J10: 0.04 | K10: 0.79 | L10: 0 | M10: 0 | N10: 0 | O10: 0 | P10: 0 | Q10: 0.79 | R10: 0 | ZZ10: CARD_HEART_MOM_02
A11: MOTHERDAY_ILOVEYOUMOM | B11: 10 | C11: MOTHERDAY_ILOVEYOUMOM_KT_35TRP_Broad_diy gifts for mom | D11: Keyword (Từ khóa) | E11: diy gifts for mom | F11: [[Broad]-[0.6]-[35T-35R-35P]] | G11: Enable | H11: 1683 | I11: 14 | J11: 0.0083 | K11: 11.03 | L11: 19.98 | M11: 2 | N11: 2 | O11: 0.14 | P11: 0.5521 | Q11: 0.79 | R11: 1.81 | ZZ11: CARVISOR_DAD
A12: MOTHERDAY_ILOVEYOUMOM | B12: 11 | C12: MOTHERDAY_ILOVEYOUMOM_KT_35TRP_Exact_diy love notes | D12: Keyword (Từ khóa) | E12: diy love notes | F12: [[Exact]-[0.6]-[35T-35R-35P]] | G12: Enable | H12: 17 | I12: 0 | J12: 0 | K12: 0 | L12: 0 | M12: 0 | N12: 0 | O12: 0 | P12: 0 | Q12: 0 | R12: 0 | ZZ12: CARVISOR_MOM
A13: MOTHERDAY_ILOVEYOUMOM | B13: 12 | C13: MOTHERDAY_ILOVEYOUMOM_KT_35TRP_phrase_diy love notes | D13: Keyword (Từ khóa) | E13: diy love notes | F13: [[Phrase]-[0.6]-[35T-35R-35P]] | G13: Enable | H13: 37 | I13: 1 | J13: 0.027 | K13: 0.79 | L13: 0 | M13: 0 | N13: 0 | O13: 0 | P13: 0 | Q13: 0.79 | R13: 0 | ZZ13: CS-S8XU-RCDA
... A56: MOTHERDAY_ILOVEYOUMOM | B56: 55 | C56: MOTHERDAY_ILOVEYOUMOM_AUTO | D56: Product Targeting | E56: loose-match | F56: [[targeting]-[0.0]-[20T-20R-20P]] | G56: No-active | H56: 0 | I56: 0 | J56: 0 | K56: 0 | L56: 0 | M56: 0 | N56: 0 | O56: 0 | P56: 0 | Q56: 0 | R56: 0 | ZZ56: bile jar-02
A57: MOTHERDAY_ILOVEYOUMOM | B57: 56 | C57: MOTHERDAY_ILOVEYOUMOM_AUTO | D57: Product Targeting | E57: substitutes | F57: [[targeting]-[0.0]-[20T-20R-20P]] | G57: No-active | H57: 0 | I57: 0 | J57: 0 | K57: 0 | L57: 0 | M57: 0 | N57: 0 | O57: 0 | P57: 0 | Q57: 0 | R57: 0
A58: FATHERDAY_DADHAT | B58: 1 | C58: FATHERDAY_DADHAT_KT_phrase_black trucker hat_30TRP | D58: Keyword (Từ khóa) | E58: black trucker hat | F58: [[Phrase]-[0.77]-[30T-30R-30P]] | G58: Enable | H58: 1 | I58: 0 | J58: 0 | K58: 0 | L58: 0 | M58: 0 | N58: 0 | O58: 0 | P58: 0 | Q58: 0 | R58: 0
A59: FATHERDAY_DADHAT | B59: 2 | C59: FATHERDAY_DADHAT_KT_broad_dad baseball cap gift_20TRP | D59: Keyword (Từ khóa) | E59: dad baseball cap gift | F59: [[Broad]-[0.3]-[20T-20R-20P]] | G59: Enable | H59: 3 | I59: 0 | J59: 0 | K59: 0 | L59: 0 | M59: 0 | N59: 0 | O59: 0 | P59: 0 | Q59: 0 | R59: 0
A60: FATHERDAY_DADHAT | B60: 3 | C60: FATHERDAY_DADHAT_KT_exact_dad_hat_35TRP_20260423 | D60: Keyword (Từ khóa) | E60: dad hat | F60: [[Exact]-[0.7]-[35T-35R-35P]] | G60: Enable | H60: 1295 | I60: 5 | J60: 0.0039 | K60: 4.7 | L60: 15.98 | M60: 1 | N60: 1 | O60: 0.2 | P60: 0.2941 | Q60: 0.94 | R60: 3.4
A61: FATHERDAY_DADHAT | B61: 4 | C61: FATHERDAY_DADHAT_KT_phrase_dad hat_30TRP | D61: Keyword (Từ khóa) | E61: dad hat | F61: [[Phrase]-[0.65]-[30T-30R-30P]] | G61: Enable | H61: 784 | I61: 5 | J61: 0.0064 | K61: 4.2 | L61: 15.98 | M61: 1 | N61: 1 | O61: 0.2 | P61: 0.2628 | Q61: 0.84 | R61: 3.8
A62: FATHERDAY_DADHAT | B62: 5 | C62: FATHERDAY_DADHAT_KT_phrase_dad_hat_30TRP_20260423 | D62: Keyword (Từ khóa) | E62: dad hat | F62: [[Phrase]-[0.6]-[30T-30R-30P]] | G62: Enable | H62: 4 | I62: 0 | J62: 0 | K62: 0 | L62: 0 | M62: 0 | N62: 0 | O62: 0 | P62: 0 | Q62: 0 | R62: 0
A63: FATHERDAY_DADHAT | B63: 6 | C63: FATHERDAY_DADHAT_KT_broad_dad hat_20TRP | D63: Keyword (Từ khóa) | E63: dad hat | F63: [[Broad]-[0.3]-[20T-20R-20P]] | G63: Enable | H63: 12 | I63: 0 | J63: 0 | K63: 0 | L63: 0 | M63: 0 | N63: 0 | O63: 0 | P63: 0 | Q63: 0 | R63: 0
A64: FATHERDAY_DADHAT | B64: 7 | C64: FATHERDAY_DADHAT_KT_phrase_dad trucker hat_30TRP | D64: Keyword (Từ khóa) | E64: dad trucker hat | F64: [[Phrase]-[0.98]-[30T-30R-30P]] | G64: Enable | H64: 246 | I64: 3 | J64: 0.0122 | K64: 3.77 | L64: 0 | M64: 0 | N64: 0 | O64: 0 | P64: 0 | Q64: 1.26 | R64: 0
A65: FATHERDAY_DADHAT | B65: 8 | C65: FATHERDAY_DADHAT_KT_broad_dad trucker hat_20TRP | D65: Keyword (Từ khóa) | E65: dad trucker hat | F65: [[Broad]-[0.3]-[20T-20R-20P]] | G65: Enable | H65: 2 | I65: 0 | J65: 0 | K65: 0 | L65: 0 | M65: 0 | N65: 0 | O65: 0 | P65: 0 | Q65: 0 | R65: 0
A66: FATHERDAY_DADHAT | B66: 9 | C66: FATHERDAY_DADHAT_KT_phrase_fathers_day_gift_30TRP_20260423 | D66: Keyword (Từ khóa) | E66: fathers day gift | F66: [[Phrase]-[0.4]-[30T-30R-30P]] | G66: Enable | H66: 1 | I66: 0 | J66: 0 | K66: 0 | L66: 0 | M66: 0 | N66: 0 | O66: 0 | P66: 0 | Q66: 0 | R66: 0
A67: FATHERDAY_DADHAT | B67: 10 | C67: FATHERDAY_DADHAT_KT_exact_fathers_day_hat_for_men_35TRP_20260423 | D67: Keyword (Từ khóa) | E67: fathers day hat for men | F67: [[Exact]-[0.7]-[35T-35R-35P]] | G67: Enable | H67: 2 | I67: 0 | J67: 0 | K67: 0 | L67: 0 | M67: 0 | N67: 0 | O67: 0 | P67: 0 | Q67: 0 | R67: 0
A68: FATHERDAY_DADHAT | B68: 11 | C68: FATHERDAY_DADHAT_KT_broad_gift for dad hat_20TRP | D68: Keyword (Từ khóa) | E68: gift for dad hat | F68: [[Broad]-[0.3]-[20T-20R-20P]] | G68: Enable | H68: 3 | I68: 0 | J68: 0 | K68: 0 | L68: 0 | M68: 0 | N68: 0 | O68: 0 | P68: 0 | Q68: 0 | R68: 0
... A277: FATHERDAY_DADJOKESJAR | B277: 50 | C277: FATHERDAY_DADJOKESJAR_KT_phrase_presents_for_dad_40TRP_20260423 | D277: Keyword (Từ khóa) | E277: presents for dad | F277: [[Phrase]-[0.4]-[40T-40R-40P]] | G277: Enable | H277: 3 | I277: 0 | J277: 0 | K277: 0 | L277: 0 | M277: 0 | N277: 0 | O277: 0 | P277: 0 | Q277: 0 | R277: 0
A278: FATHERDAY_DADJOKESJAR | B278: 51 | E278: best dad gifts | F278: Phrase 0.4, 40TRP | G278: No-active | H278: 0 | I278: 0 | J278: 0 | K278: 0 | L278: 0 | M278: 0 | N278: 0 | O278: 0 | P278: 0 | Q278: 0 | R278: 0
A279: FATHERDAY_DADJOKESJAR | B279: 52 | E279: birthday card for dad | F279: Phrase 0.4, 40TRP | G279: No-active | H279: 0 | I279: 0 | J279: 0 | K279: 0 | L279: 0 | M279: 0 | N279: 0 | O279: 0 | P279: 0 | Q279: 0 | R279: 0
A280: FATHERDAY_DADJOKESJAR | B280: 53 | E280: birthday card for dad from daughter | F280: Phrase 0.4, 40TRP | G280: No-active | H280: 0 | I280: 0 | J280: 0 | K280: 0 | L280: 0 | M280: 0 | N280: 0 | O280: 0 | P280: 0 | Q280: 0 | R280: 0
A281: FATHERDAY_DADJOKESJAR | B281: 54 | E281: birthday dad | F281: Phrase 0.4, 40TRP | G281: No-active | H281: 0 | I281: 0 | J281: 0 | K281: 0 | L281: 0 | M281: 0 | N281: 0 | O281: 0 | P281: 0 | Q281: 0 | R281: 0
A282: FATHERDAY_DADJOKESJAR | B282: 55 | E282: birthday for dad | F282: Phrase 0.4, 40TRP | G282: No-active | H282: 0 | I282: 0 | J282: 0 | K282: 0 | L282: 0 | M282: 0 | N282: 0 | O282: 0 | P282: 0 | Q282: 0 | R282: 0
A283: FATHERDAY_DADJOKESJAR | B283: 56 | E283: birthday gift for dad from daughter | F283: Phrase 0.4, 40TRP | G283: No-active | H283: 0 | I283: 0 | J283: 0 | K283: 0 | L283: 0 | M283: 0 | N283: 0 | O283: 0 | P283: 0 | Q283: 0 | R283: 0
A284: FATHERDAY_DADJOKESJAR | B284: 57 | E284: birthday gift for men | F284: Phrase 0.4, 40TRP | G284: No-active | H284: 0 | I284: 0 | J284: 0 | K284: 0 | L284: 0 | M284: 0 | N284: 0 | O284: 0 | P284: 0 | Q284: 0 | R284: 0
A285: FATHERDAY_DADJOKESJAR | B285: 58 | E285: birthday gifts for dad | F285: Phrase 0.4, 40TRP | G285: No-active | H285: 0 | I285: 0 | J285: 0 | K285: 0 | L285: 0 | M285: 0 | N285: 0 | O285: 0 | P285: 0 | Q285: 0 | R285: 0
A286: FATHERDAY_DADJOKESJAR | B286: 59 | E286: birthday gifts for dad from daughter | F286: Phrase 0.4, 40TRP | G286: No-active | H286: 0 | I286: 0 | J286: 0 | K286: 0 | L286: 0 | M286: 0 | N286: 0 | O286: 0 | P286: 0 | Q286: 0 | R286: 0
A287: FATHERDAY_DADJOKESJAR | B287: 60 | E287: boy dad gifts | F287: Phrase 0.4, 40TRP | G287: No-active | H287: 0 | I287: 0 | J287: 0 | K287: 0 | L287: 0 | M287: 0 | N287: 0 | O287: 0 | P287: 0 | Q287: 0 | R287: 0
A288: FATHERDAY_DADJOKESJAR | B288: 61 | E288: cool gadgets | F288: Phrase 0.4, 40TRP | G288: No-active | H288: 0 | I288: 0 | J288: 0 | K288: 0 | L288: 0 | M288: 0 | N288: 0 | O288: 0 | P288: 0 | Q288: 0 | R288: 0
A289: FATHERDAY_DADJOKESJAR | B289: 62 | E289: dad birthday | F289: Phrase 0.4, 40TRP | G289: No-active | H289: 0 | I289: 0 | J289: 0 | K289: 0 | L289: 0 | M289: 0 | N289: 0 | O289: 0 | P289: 0 | Q289: 0 | R289: 0
... A320: FATHERDAY_DADJOKESJAR | B320: 93 | E320: thoughtful gifts for men | F320: Phrase 0.4, 40TRP | G320: No-active | H320: 0 | I320: 0 | J320: 0 | K320: 0 | L320: 0 | M320: 0 | N320: 0 | O320: 0 | P320: 0 | Q320: 0 | R320: 0
...

Sheet Dashboard
A1: CHỌN SKU: | B1: B2-WBSR-5J3P
A2: GIAI ĐOẠN: | B2: Maintain
B3: Spend | C3: Sales | D3: Clicks | E3: Impressions | F3: ACOS | G3: CVR | H3: CTR
A4: TỔNG QUAN | B4: =SUMIFS('RAW_SKU_DATA'!K:K, 'RAW_SKU_DATA'!A:A, $B$1) -> 0 | C4: =SUMIFS('RAW_SKU_DATA'!L:L, 'RAW_SKU_DATA'!A:A, $B$1) -> 0 | D4: =SUMIFS('RAW_SKU_DATA'!I:I, 'RAW_SKU_DATA'!A:A, $B$1) -> 0 | E4: =SUMIFS('RAW_SKU_DATA'!H:H, 'RAW_SKU_DATA'!A:A, $B$1) -> 0 | F4: =IF(C4=0, 0, B4/C4) -> 0 | G4: =IF(D4=0, 0, =SUMIFS('RAW_SKU_DATA'!M:M, 'RAW_SKU_DATA'!A:A, $B$1)/D4) -> 0 | H4: =IF(E4=0, 0, D4/E4) -> 0
A6: Campaign | B6: Impressions | C6: Clicks | D6: CTR | E6: Spend | F6: Sales | G6: Orders | H6: CVR | I6: ACOS
A7: {=_xlfn.UNIQUE(_xlfn._xlws.FILTER('RAW_SKU_DATA'!C:C, 'RAW_SKU_DATA'!A:A=$B$1, ""))} -> 0 | B7: =IF($A$7="","", SUMIFS('RAW_SKU_DATA'!H:H, 'RAW_SKU_DATA'!A:A, $B$1, 'RAW_SKU_DATA'!C:C, $A$7)) -> 0 | C7: =IF($A$7="","", SUMIFS('RAW_SKU_DATA'!I:I, 'RAW_SKU_DATA'!A:A, $B$1, 'RAW_SKU_DATA'!C:C, $A$7)) -> 0 | D7: =IF(OR($A$7="", B7=0), 0, C7/B7) -> 0 | E7: =IF($A$7="","", SUMIFS('RAW_SKU_DATA'!K:K, 'RAW_SKU_DATA'!A:A, $B$1, 'RAW_SKU_DATA'!C:C, $A$7)) -> 0 | F7: =IF($A$7="","", SUMIFS('RAW_SKU_DATA'!L:L, 'RAW_SKU_DATA'!A:A, $B$1, 'RAW_SKU_DATA'!C:C, $A$7)) -> 0 | G7: =IF($A$7="","", SUMIFS('RAW_SKU_DATA'!M:M, 'RAW_SKU_DATA'!A:A, $B$1, 'RAW_SKU_DATA'!C:C, $A$7)) -> 0 | H7: =IF(OR($A$7="", C7=0), 0, G7/C7) -> 0 | I7: =IF(OR($A$7="", F7=0), 0, E7/F7) -> 0
B8: =IF($A$8="","", SUMIFS('RAW_SKU_DATA'!H:H, 'RAW_SKU_DATA'!A:A, $B$1, 'RAW_SKU_DATA'!C:C, $A$8)) -> 0 | C8: =IF($A$8="","", SUMIFS('RAW_SKU_DATA'!I:I, 'RAW_SKU_DATA'!A:A, $B$1, 'RAW_SKU_DATA'!C:C, $A$8)) -> 0 | D8: =IF(OR($A$8="", B8=0), 0, C8/B8) -> 0 | E8: =IF($A$8="","", SUMIFS('RAW_SKU_DATA'!K:K, 'RAW_SKU_DATA'!A:A, $B$1, 'RAW_SKU_DATA'!C:C, $A$8)) -> 0 | F8: =IF($A$8="","", SUMIFS('RAW_SKU_DATA'!L:L, 'RAW_SKU_DATA'!A:A, $B$1, 'RAW_SKU_DATA'!C:C, $A$8)) -> 0 | G8: =IF($A$8="","", SUMIFS('RAW_SKU_DATA'!M:M, 'RAW_SKU_DATA'!A:A, $B$1, 'RAW_SKU_DATA'!C:C, $A$8)) -> 0 | H8: =IF(OR($A$8="", C8=0), 0, G8/C8) -> 0 | I8: =IF(OR($A$8="", F8=0), 0, E8/F8) -> 0
B9: =IF($A$9="","", SUMIFS('RAW_SKU_DATA'!H:H, 'RAW_SKU_DATA'!A:A, $B$1, 'RAW_SKU_DATA'!C:C, $A$9)) -> 0 | C9: =IF($A$9="","", SUMIFS('RAW_SKU_DATA'!I:I, 'RAW_SKU_DATA'!A:A, $B$1, 'RAW_SKU_DATA'!C:C, $A$9)) -> 0 | D9: =IF(OR($A$9="", B9=0), 0, C9/B9) -> 0 | E9: =IF($A$9="","", SUMIFS('RAW_SKU_DATA'!K:K, 'RAW_SKU_DATA'!A:A, $B$1, 'RAW_SKU_DATA'!C:C, $A$9)) -> 0 | F9: =IF($A$9="","", SUMIFS('RAW_SKU_DATA'!L:L, 'RAW_SKU_DATA'!A:A, $B$1, 'RAW_SKU_DATA'!C:C, $A$9)) -> 0 | G9: =IF($A$9="","", SUMIFS('RAW_SKU_DATA'!M:M, 'RAW_SKU_DATA'!A:A, $B$1, 'RAW_SKU_DATA'!C:C, $A$9)) -> 0 | H9: =IF(OR($A$9="", C9=0), 0, G9/C9) -> 0 | I9: =IF(OR($A$9="", F9=0), 0, E9/F9) -> 0
B10: =IF($A$10="","", SUMIFS('RAW_SKU_DATA'!H:H, 'RAW_SKU_DATA'!A:A, $B$1, 'RAW_SKU_DATA'!C:C, $A$10)) -> 0 | C10: =IF($A$10="","", SUMIFS('RAW_SKU_DATA'!I:I, 'RAW_SKU_DATA'!A:A, $B$1, 'RAW_SKU_DATA'!C:C, $A$10)) -> 0 | D10: =IF(OR($A$10="", B10=0), 0, C10/B10) -> 0 | E10: =IF($A$10="","", SUMIFS('RAW_SKU_DATA'!K:K, 'RAW_SKU_DATA'!A:A, $B$1, 'RAW_SKU_DATA'!C:C, $A$10)) -> 0 | F10: =IF($A$10="","", SUMIFS('RAW_SKU_DATA'!L:L, 'RAW_SKU_DATA'!A:A, $B$1, 'RAW_SKU_DATA'!C:C, $A$10)) -> 0 | G10: =IF($A$10="","", SUMIFS('RAW_SKU_DATA'!M:M, 'RAW_SKU_DATA'!A:A, $B$1, 'RAW_SKU_DATA'!C:C, $A$10)) -> 0 | H10: =IF(OR($A$10="", C10=0), 0, G10/C10) -> 0 | I10: =IF(OR($A$10="", F10=0), 0, E10/F10) -> 0
B11: =IF($A$11="","", SUMIFS('RAW_SKU_DATA'!H:H, 'RAW_SKU_DATA'!A:A, $B$1, 'RAW_SKU_DATA'!C:C, $A$11)) -> 0 | C11: =IF($A$11="","", SUMIFS('RAW_SKU_DATA'!I:I, 'RAW_SKU_DATA'!A:A, $B$1, 'RAW_SKU_DATA'!C:C, $A$11)) -> 0 | D11: =IF(OR($A$11="", B11=0), 0, C11/B11) -> 0 | E11: =IF($A$11="","", SUMIFS('RAW_SKU_DATA'!K:K, 'RAW_SKU_DATA'!A:A, $B$1, 'RAW_SKU_DATA'!C:C, $A$11)) -> 0 | F11: =IF($A$11="","", SUMIFS('RAW_SKU_DATA'!L:L, 'RAW_SKU_DATA'!A:A, $B$1, 'RAW_SKU_DATA'!C:C, $A$11)) -> 0 | G11: =IF($A$11="","", SUMIFS('RAW_SKU_DATA'!M:M, 'RAW_SKU_DATA'!A:A, $B$1, 'RAW_SKU_DATA'!C:C, $A$11)) -> 0 | H11: =IF(OR($A$11="", C11=0), 0, G11/C11) -> 0 | I11: =IF(OR($A$11="", F11=0), 0, E11/F11) -> 0
B12: =IF($A$12="","", SUMIFS('RAW_SKU_DATA'!H:H, 'RAW_SKU_DATA'!A:A, $B$1, 'RAW_SKU_DATA'!C:C, $A$12)) -> 0 | C12: =IF($A$12="","", SUMIFS('RAW_SKU_DATA'!I:I, 'RAW_SKU_DATA'!A:A, $B$1, 'RAW_SKU_DATA'!C:C, $A$12)) -> 0 | D12: =IF(OR($A$12="", B12=0), 0, C12/B12) -> 0 | E12: =IF($A$12="","", SUMIFS('RAW_SKU_DATA'!K:K, 'RAW_SKU_DATA'!A:A, $B$1, 'RAW_SKU_DATA'!C:C, $A$12)) -> 0 | F12: =IF($A$12="","", SUMIFS('RAW_SKU_DATA'!L:L, 'RAW_SKU_DATA'!A:A, $B$1, 'RAW_SKU_DATA'!C:C, $A$12)) -> 0 | G12: =IF($A$12="","", SUMIFS('RAW_SKU_DATA'!M:M, 'RAW_SKU_DATA'!A:A, $B$1, 'RAW_SKU_DATA'!C:C, $A$12)) -> 0 | H12: =IF(OR($A$12="", C12=0), 0, G12/C12) -> 0 | I12: =IF(OR($A$12="", F12=0), 0, E12/F12) -> 0
B13: =IF($A$13="","", SUMIFS('RAW_SKU_DATA'!H:H, 'RAW_SKU_DATA'!A:A, $B$1, 'RAW_SKU_DATA'!C:C, $A$13)) -> 0 | C13: =IF($A$13="","", SUMIFS('RAW_SKU_DATA'!I:I, 'RAW_SKU_DATA'!A:A, $B$1, 'RAW_SKU_DATA'!C:C, $A$13)) -> 0 | D13: =IF(OR($A$13="", B13=0), 0, C13/B13) -> 0 | E13: =IF($A$13="","", SUMIFS('RAW_SKU_DATA'!K:K, 'RAW_SKU_DATA'!A:A, $B$1, 'RAW_SKU_DATA'!C:C, $A$13)) -> 0 | F13: =IF($A$13="","", SUMIFS('RAW_SKU_DATA'!L:L, 'RAW_SKU_DATA'!A:A, $B$1, 'RAW_SKU_DATA'!C:C, $A$13)) -> 0 | G13: =IF($A$13="","", SUMIFS('RAW_SKU_DATA'!M:M, 'RAW_SKU_DATA'!A:A, $B$1, 'RAW_SKU_DATA'!C:C, $A$13)) -> 0 | H13: =IF(OR($A$13="", C13=0), 0, G13/C13) -> 0 | I13: =IF(OR($A$13="", F13=0), 0, E13/F13) -> 0
B14: =IF($A$14="","", SUMIFS('RAW_SKU_DATA'!H:H, 'RAW_SKU_DATA'!A:A, $B$1, 'RAW_SKU_DATA'!C:C, $A$14)) -> 0 | C14: =IF($A$14="","", SUMIFS('RAW_SKU_DATA'!I:I, 'RAW_SKU_DATA'!A:A, $B$1, 'RAW_SKU_DATA'!C:C, $A$14)) -> 0 | D14: =IF(OR($A$14="", B14=0), 0, C14/B14) -> 0 | E14: =IF($A$14="","", SUMIFS('RAW_SKU_DATA'!K:K, 'RAW_SKU_DATA'!A:A, $B$1, 'RAW_SKU_DATA'!C:C, $A$14)) -> 0 | F14: =IF($A$14="","", SUMIFS('RAW_SKU_DATA'!L:L, 'RAW_SKU_DATA'!A:A, $B$1, 'RAW_SKU_DATA'!C:C, $A$14)) -> 0 | G14: =IF($A$14="","", SUMIFS('RAW_SKU_DATA'!M:M, 'RAW_SKU_DATA'!A:A, $B$1, 'RAW_SKU_DATA'!C:C, $A$14)) -> 0 | H14: =IF(OR($A$14="", C14=0), 0, G14/C14) -> 0 | I14: =IF(OR($A$14="", F14=0), 0, E14/F14) -> 0
B15: =IF($A$15="","", SUMIFS('RAW_SKU_DATA'!H:H, 'RAW_SKU_DATA'!A:A, $B$1, 'RAW_SKU_DATA'!C:C, $A$15)) -> 0 | C15: =IF($A$15="","", SUMIFS('RAW_SKU_DATA'!I:I, 'RAW_SKU_DATA'!A:A, $B$1, 'RAW_SKU_DATA'!C:C, $A$15)) -> 0 | D15: =IF(OR($A$15="", B15=0), 0, C15/B15) -> 0 | E15: =IF($A$15="","", SUMIFS('RAW_SKU_DATA'!K:K, 'RAW_SKU_DATA'!A:A, $B$1, 'RAW_SKU_DATA'!C:C, $A$15)) -> 0 | F15: =IF($A$15="","", SUMIFS('RAW_SKU_DATA'!L:L, 'RAW_SKU_DATA'!A:A, $B$1, 'RAW_SKU_DATA'!C:C, $A$15)) -> 0 | G15: =IF($A$15="","", SUMIFS('RAW_SKU_DATA'!M:M, 'RAW_SKU_DATA'!A:A, $B$1, 'RAW_SKU_DATA'!C:C, $A$15)) -> 0 | H15: =IF(OR($A$15="", C15=0), 0, G15/C15) -> 0 | I15: =IF(OR($A$15="", F15=0), 0, E15/F15) -> 0
B16: =IF($A$16="","", SUMIFS('RAW_SKU_DATA'!H:H, 'RAW_SKU_DATA'!A:A, $B$1, 'RAW_SKU_DATA'!C:C, $A$16)) -> 0 | C16: =IF($A$16="","", SUMIFS('RAW_SKU_DATA'!I:I, 'RAW_SKU_DATA'!A:A, $B$1, 'RAW_SKU_DATA'!C:C, $A$16)) -> 0 | D16: =IF(OR($A$16="", B16=0), 0, C16/B16) -> 0 | E16: =IF($A$16="","", SUMIFS('RAW_SKU_DATA'!K:K, 'RAW_SKU_DATA'!A:A, $B$1, 'RAW_SKU_DATA'!C:C, $A$16)) -> 0 | F16: =IF($A$16="","", SUMIFS('RAW_SKU_DATA'!L:L, 'RAW_SKU_DATA'!A:A, $B$1, 'RAW_SKU_DATA'!C:C, $A$16)) -> 0 | G16: =IF($A$16="","", SUMIFS('RAW_SKU_DATA'!M:M, 'RAW_SKU_DATA'!A:A, $B$1, 'RAW_SKU_DATA'!C:C, $A$16)) -> 0 | H16: =IF(OR($A$16="", C16=0), 0, G16/C16) -> 0 | I16: =IF(OR($A$16="", F16=0), 0, E16/F16) -> 0
B17: =IF($A$17="","", SUMIFS('RAW_SKU_DATA'!H:H, 'RAW_SKU_DATA'!A:A, $B$1, 'RAW_SKU_DATA'!C:C, $A$17)) -> 0 | C17: =IF($A$17="","", SUMIFS('RAW_SKU_DATA'!I:I, 'RAW_SKU_DATA'!A:A, $B$1, 'RAW_SKU_DATA'!C:C, $A$17)) -> 0 | D17: =IF(OR($A$17="", B17=0), 0, C17/B17) -> 0 | E17: =IF($A$17="","", SUMIFS('RAW_SKU_DATA'!K:K, 'RAW_SKU_DATA'!A:A, $B$1, 'RAW_SKU_DATA'!C:C, $A$17)) -> 0 | F17: =IF($A$17="","", SUMIFS('RAW_SKU_DATA'!L:L, 'RAW_SKU_DATA'!A:A, $B$1, 'RAW_SKU_DATA'!C:C, $A$17)) -> 0 | G17: =IF($A$17="","", SUMIFS('RAW_SKU_DATA'!M:M, 'RAW_SKU_DATA'!A:A, $B$1, 'RAW_SKU_DATA'!C:C, $A$17)) -> 0 | H17: =IF(OR($A$17="", C17=0), 0, G17/C17) -> 0 | I17: =IF(OR($A$17="", F17=0), 0, E17/F17) -> 0
B18: =IF($A$18="","", SUMIFS('RAW_SKU_DATA'!H:H, 'RAW_SKU_DATA'!A:A, $B$1, 'RAW_SKU_DATA'!C:C, $A$18)) -> 0 | C18: =IF($A$18="","", SUMIFS('RAW_SKU_DATA'!I:I, 'RAW_SKU_DATA'!A:A, $B$1, 'RAW_SKU_DATA'!C:C, $A$18)) -> 0 | D18: =IF(OR($A$18="", B18=0), 0, C18/B18) -> 0 | E18: =IF($A$18="","", SUMIFS('RAW_SKU_DATA'!K:K, 'RAW_SKU_DATA'!A:A, $B$1, 'RAW_SKU_DATA'!C:C, $A$18)) -> 0 | F18: =IF($A$18="","", SUMIFS('RAW_SKU_DATA'!L:L, 'RAW_SKU_DATA'!A:A, $B$1, 'RAW_SKU_DATA'!C:C, $A$18)) -> 0 | G18: =IF($A$18="","", SUMIFS('RAW_SKU_DATA'!M:M, 'RAW_SKU_DATA'!A:A, $B$1, 'RAW_SKU_DATA'!C:C, $A$18)) -> 0 | H18: =IF(OR($A$18="", C18=0), 0, G18/C18) -> 0 | I18: =IF(OR($A$18="", F18=0), 0, E18/F18) -> 0
B19: =IF($A$19="","", SUMIFS('RAW_SKU_DATA'!H:H, 'RAW_SKU_DATA'!A:A, $B$1, 'RAW_SKU_DATA'!C:C, $A$19)) -> 0 | C19: =IF($A$19="","", SUMIFS('RAW_SKU_DATA'!I:I, 'RAW_SKU_DATA'!A:A, $B$1, 'RAW_SKU_DATA'!C:C, $A$19)) -> 0 | D19: =IF(OR($A$19="", B19=0), 0, C19/B19) -> 0 | E19: =IF($A$19="","", SUMIFS('RAW_SKU_DATA'!K:K, 'RAW_SKU_DATA'!A:A, $B$1, 'RAW_SKU_DATA'!C:C, $A$19)) -> 0 | F19: =IF($A$19="","", SUMIFS('RAW_SKU_DATA'!L:L, 'RAW_SKU_DATA'!A:A, $B$1, 'RAW_SKU_DATA'!C:C, $A$19)) -> 0 | G19: =IF($A$19="","", SUMIFS('RAW_SKU_DATA'!M:M, 'RAW_SKU_DATA'!A:A, $B$1, 'RAW_SKU_DATA'!C:C, $A$19)) -> 0 | H19: =IF(OR($A$19="", C19=0), 0, G19/C19) -> 0 | I19: =IF(OR($A$19="", F19=0), 0, E19/F19) -> 0
B20: =IF($A$20="","", SUMIFS('RAW_SKU_DATA'!H:H, 'RAW_SKU_DATA'!A:A, $B$1, 'RAW_SKU_DATA'!C:C, $A$20)) -> 0 | C20: =IF($A$20="","", SUMIFS('RAW_SKU_DATA'!I:I, 'RAW_SKU_DATA'!A:A, $B$1, 'RAW_SKU_DATA'!C:C, $A$20)) -> 0 | D20: =IF(OR($A$20="", B20=0), 0, C20/B20) -> 0 | E20: =IF($A$20="","", SUMIFS('RAW_SKU_DATA'!K:K, 'RAW_SKU_DATA'!A:A, $B$1, 'RAW_SKU_DATA'!C:C, $A$20)) -> 0 | F20: =IF($A$20="","", SUMIFS('RAW_SKU_DATA'!L:L, 'RAW_SKU_DATA'!A:A, $B$1, 'RAW_SKU_DATA'!C:C, $A$20)) -> 0 | G20: =IF($A$20="","", SUMIFS('RAW_SKU_DATA'!M:M, 'RAW_SKU_DATA'!A:A, $B$1, 'RAW_SKU_DATA'!C:C, $A$20)) -> 0 | H20: =IF(OR($A$20="", C20=0), 0, G20/C20) -> 0 | I20: =IF(OR($A$20="", F20=0), 0, E20/F20) -> 0
B21: =IF($A$21="","", SUMIFS('RAW_SKU_DATA'!H:H, 'RAW_SKU_DATA'!A:A, $B$1, 'RAW_SKU_DATA'!C:C, $A$21)) -> 0 | C21: =IF($A$21="","", SUMIFS('RAW_SKU_DATA'!I:I, 'RAW_SKU_DATA'!A:A, $B$1, 'RAW_SKU_DATA'!C:C, $A$21)) -> 0 | D21: =IF(OR($A$21="", B21=0), 0, C21/B21) -> 0 | E21: =IF($A$21="","", SUMIFS('RAW_SKU_DATA'!K:K, 'RAW_SKU_DATA'!A:A, $B$1, 'RAW_SKU_DATA'!C:C, $A$21)) -> 0 | F21: =IF($A$21="","", SUMIFS('RAW_SKU_DATA'!L:L, 'RAW_SKU_DATA'!A:A, $B$1, 'RAW_SKU_DATA'!C:C, $A$21)) -> 0 | G21: =IF($A$21="","", SUMIFS('RAW_SKU_DATA'!M:M, 'RAW_SKU_DATA'!A:A, $B$1, 'RAW_SKU_DATA'!C:C, $A$21)) -> 0 | H21: =IF(OR($A$21="", C21=0), 0, G21/C21) -> 0 | I21: =IF(OR($A$21="", F21=0), 0, E21/F21) -> 0
B22: =IF($A$22="","", SUMIFS('RAW_SKU_DATA'!H:H, 'RAW_SKU_DATA'!A:A, $B$1, 'RAW_SKU_DATA'!C:C, $A$22)) -> 0 | C22: =IF($A$22="","", SUMIFS('RAW_SKU_DATA'!I:I, 'RAW_SKU_DATA'!A:A, $B$1, 'RAW_SKU_DATA'!C:C, $A$22)) -> 0 | D22: =IF(OR($A$22="", B22=0), 0, C22/B22) -> 0 | E22: =IF($A$22="","", SUMIFS('RAW_SKU_DATA'!K:K, 'RAW_SKU_DATA'!A:A, $B$1, 'RAW_SKU_DATA'!C:C, $A$22)) -> 0 | F22: =IF($A$22="","", SUMIFS('RAW_SKU_DATA'!L:L, 'RAW_SKU_DATA'!A:A, $B$1, 'RAW_SKU_DATA'!C:C, $A$22)) -> 0 | G22: =IF($A$22="","", SUMIFS('RAW_SKU_DATA'!M:M, 'RAW_SKU_DATA'!A:A, $B$1, 'RAW_SKU_DATA'!C:C, $A$22)) -> 0 | H22: =IF(OR($A$22="", C22=0), 0, G22/C22) -> 0 | I22: =IF(OR($A$22="", F22=0), 0, E22/F22) -> 0
B23: =IF($A$23="","", SUMIFS('RAW_SKU_DATA'!H:H, 'RAW_SKU_DATA'!A:A, $B$1, 'RAW_SKU_DATA'!C:C, $A$23)) -> 0 | C23: =IF($A$23="","", SUMIFS('RAW_SKU_DATA'!I:I, 'RAW_SKU_DATA'!A:A, $B$1, 'RAW_SKU_DATA'!C:C, $A$23)) -> 0 | D23: =IF(OR($A$23="", B23=0), 0, C23/B23) -> 0 | E23: =IF($A$23="","", SUMIFS('RAW_SKU_DATA'!K:K, 'RAW_SKU_DATA'!A:A, $B$1, 'RAW_SKU_DATA'!C:C, $A$23)) -> 0 | F23: =IF($A$23="","", SUMIFS('RAW_SKU_DATA'!L:L, 'RAW_SKU_DATA'!A:A, $B$1, 'RAW_SKU_DATA'!C:C, $A$23)) -> 0 | G23: =IF($A$23="","", SUMIFS('RAW_SKU_DATA'!M:M, 'RAW_SKU_DATA'!A:A, $B$1, 'RAW_SKU_DATA'!C:C, $A$23)) -> 0 | H23: =IF(OR($A$23="", C23=0), 0, G23/C23) -> 0 | I23: =IF(OR($A$23="", F23=0), 0, E23/F23) -> 0
B24: =IF($A$24="","", SUMIFS('RAW_SKU_DATA'!H:H, 'RAW_SKU_DATA'!A:A, $B$1, 'RAW_SKU_DATA'!C:C, $A$24)) -> 0 | C24: =IF($A$24="","", SUMIFS('RAW_SKU_DATA'!I:I, 'RAW_SKU_DATA'!A:A, $B$1, 'RAW_SKU_DATA'!C:C, $A$24)) -> 0 | D24: =IF(OR($A$24="", B24=0), 0, C24/B24) -> 0 | E24: =IF($A$24="","", SUMIFS('RAW_SKU_DATA'!K:K, 'RAW_SKU_DATA'!A:A, $B$1, 'RAW_SKU_DATA'!C:C, $A$24)) -> 0 | F24: =IF($A$24="","", SUMIFS('RAW_SKU_DATA'!L:L, 'RAW_SKU_DATA'!A:A, $B$1, 'RAW_SKU_DATA'!C:C, $A$24)) -> 0 | G24: =IF($A$24="","", SUMIFS('RAW_SKU_DATA'!M:M, 'RAW_SKU_DATA'!A:A, $B$1, 'RAW_SKU_DATA'!C:C, $A$24)) -> 0 | H24: =IF(OR($A$24="", C24=0), 0, G24/C24) -> 0 | I24: =IF(OR($A$24="", F24=0), 0, E24/F24) -> 0
B25: =IF($A$25="","", SUMIFS('RAW_SKU_DATA'!H:H, 'RAW_SKU_DATA'!A:A, $B$1, 'RAW_SKU_DATA'!C:C, $A$25)) -> 0 | C25: =IF($A$25="","", SUMIFS('RAW_SKU_DATA'!I:I, 'RAW_SKU_DATA'!A:A, $B$1, 'RAW_SKU_DATA'!C:C, $A$25)) -> 0 | D25: =IF(OR($A$25="", B25=0), 0, C25/B25) -> 0 | E25: =IF($A$25="","", SUMIFS('RAW_SKU_DATA'!K:K, 'RAW_SKU_DATA'!A:A, $B$1, 'RAW_SKU_DATA'!C:C, $A$25)) -> 0 | F25: =IF($A$25="","", SUMIFS('RAW_SKU_DATA'!L:L, 'RAW_SKU_DATA'!A:A, $B$1, 'RAW_SKU_DATA'!C:C, $A$25)) -> 0 | G25: =IF($A$25="","", SUMIFS('RAW_SKU_DATA'!M:M, 'RAW_SKU_DATA'!A:A, $B$1, 'RAW_SKU_DATA'!C:C, $A$25)) -> 0 | H25: =IF(OR($A$25="", C25=0), 0, G25/C25) -> 0 | I25: =IF(OR($A$25="", F25=0), 0, E25/F25) -> 0
B26: =IF($A$26="","", SUMIFS('RAW_SKU_DATA'!H:H, 'RAW_SKU_DATA'!A:A, $B$1, 'RAW_SKU_DATA'!C:C, $A$26)) -> 0 | C26: =IF($A$26="","", SUMIFS('RAW_SKU_DATA'!I:I, 'RAW_SKU_DATA'!A:A, $B$1, 'RAW_SKU_DATA'!C:C, $A$26)) -> 0 | D26: =IF(OR($A$26="", B26=0), 0, C26/B26) -> 0 | E26: =IF($A$26="","", SUMIFS('RAW_SKU_DATA'!K:K, 'RAW_SKU_DATA'!A:A, $B$1, 'RAW_SKU_DATA'!C:C, $A$26)) -> 0 | F26: =IF($A$26="","", SUMIFS('RAW_SKU_DATA'!L:L, 'RAW_SKU_DATA'!A:A, $B$1, 'RAW_SKU_DATA'!C:C, $A$26)) -> 0 | G26: =IF($A$26="","", SUMIFS('RAW_SKU_DATA'!M:M, 'RAW_SKU_DATA'!A:A, $B$1, 'RAW_SKU_DATA'!C:C, $A$26)) -> 0 | H26: =IF(OR($A$26="", C26=0), 0, G26/C26) -> 0 | I26: =IF(OR($A$26="", F26=0), 0, E26/F26) -> 0
B27: =IF($A$27="","", SUMIFS('RAW_SKU_DATA'!H:H, 'RAW_SKU_DATA'!A:A, $B$1, 'RAW_SKU_DATA'!C:C, $A$27)) -> 0 | C27: =IF($A$27="","", SUMIFS('RAW_SKU_DATA'!I:I, 'RAW_SKU_DATA'!A:A, $B$1, 'RAW_SKU_DATA'!C:C, $A$27)) -> 0 | D27: =IF(OR($A$27="", B27=0), 0, C27/B27) -> 0 | E27: =IF($A$27="","", SUMIFS('RAW_SKU_DATA'!K:K, 'RAW_SKU_DATA'!A:A, $B$1, 'RAW_SKU_DATA'!C:C, $A$27)) -> 0 | F27: =IF($A$27="","", SUMIFS('RAW_SKU_DATA'!L:L, 'RAW_SKU_DATA'!A:A, $B$1, 'RAW_SKU_DATA'!C:C, $A$27)) -> 0 | G27: =IF($A$27="","", SUMIFS('RAW_SKU_DATA'!M:M, 'RAW_SKU_DATA'!A:A, $B$1, 'RAW_SKU_DATA'!C:C, $A$27)) -> 0 | H27: =IF(OR($A$27="", C27=0), 0, G27/C27) -> 0 | I27: =IF(OR($A$27="", F27=0), 0, E27/F27) -> 0
B28: =IF($A$28="","", SUMIFS('RAW_SKU_DATA'!H:H, 'RAW_SKU_DATA'!A:A, $B$1, 'RAW_SKU_DATA'!C:C, $A$28)) -> 0 | C28: =IF($A$28="","", SUMIFS('RAW_SKU_DATA'!I:I, 'RAW_SKU_DATA'!A:A, $B$1, 'RAW_SKU_DATA'!C:C, $A$28)) -> 0 | D28: =IF(OR($A$28="", B28=0), 0, C28/B28) -> 0 | E28: =IF($A$28="","", SUMIFS('RAW_SKU_DATA'!K:K, 'RAW_SKU_DATA'!A:A, $B$1, 'RAW_SKU_DATA'!C:C, $A$28)) -> 0 | F28: =IF($A$28="","", SUMIFS('RAW_SKU_DATA'!L:L, 'RAW_SKU_DATA'!A:A, $B$1, 'RAW_SKU_DATA'!C:C, $A$28)) -> 0 | G28: =IF($A$28="","", SUMIFS('RAW_SKU_DATA'!M:M, 'RAW_SKU_DATA'!A:A, $B$1, 'RAW_SKU_DATA'!C:C, $A$28)) -> 0 | H28: =IF(OR($A$28="", C28=0), 0, G28/C28) -> 0 | I28: =IF(OR($A$28="", F28=0), 0, E28/F28) -> 0
B29: =IF($A$29="","", SUMIFS('RAW_SKU_DATA'!H:H, 'RAW_SKU_DATA'!A:A, $B$1, 'RAW_SKU_DATA'!C:C, $A$29)) -> 0 | C29: =IF($A$29="","", SUMIFS('RAW_SKU_DATA'!I:I, 'RAW_SKU_DATA'!A:A, $B$1, 'RAW_SKU_DATA'!C:C, $A$29)) -> 0 | D29: =IF(OR($A$29="", B29=0), 0, C29/B29) -> 0 | E29: =IF($A$29="","", SUMIFS('RAW_SKU_DATA'!K:K, 'RAW_SKU_DATA'!A:A, $B$1, 'RAW_SKU_DATA'!C:C, $A$29)) -> 0 | F29: =IF($A$29="","", SUMIFS('RAW_SKU_DATA'!L:L, 'RAW_SKU_DATA'!A:A, $B$1, 'RAW_SKU_DATA'!C:C, $A$29)) -> 0 | G29: =IF($A$29="","", SUMIFS('RAW_SKU_DATA'!M:M, 'RAW_SKU_DATA'!A:A, $B$1, 'RAW_SKU_DATA'!C:C, $A$29)) -> 0 | H29: =IF(OR($A$29="", C29=0), 0, G29/C29) -> 0 | I29: =IF(OR($A$29="", F29=0), 0, E29/F29) -> 0
B30: =IF($A$30="","", SUMIFS('RAW_SKU_DATA'!H:H, 'RAW_SKU_DATA'!A:A, $B$1, 'RAW_SKU_DATA'!C:C, $A$30)) -> 0 | C30: =IF($A$30="","", SUMIFS('RAW_SKU_DATA'!I:I, 'RAW_SKU_DATA'!A:A, $B$1, 'RAW_SKU_DATA'!C:C, $A$30)) -> 0 | D30: =IF(OR($A$30="", B30=0), 0, C30/B30) -> 0 | E30: =IF($A$30="","", SUMIFS('RAW_SKU_DATA'!K:K, 'RAW_SKU_DATA'!A:A, $B$1, 'RAW_SKU_DATA'!C:C, $A$30)) -> 0 | F30: =IF($A$30="","", SUMIFS('RAW_SKU_DATA'!L:L, 'RAW_SKU_DATA'!A:A, $B$1, 'RAW_SKU_DATA'!C:C, $A$30)) -> 0 | G30: =IF($A$30="","", SUMIFS('RAW_SKU_DATA'!M:M, 'RAW_SKU_DATA'!A:A, $B$1, 'RAW_SKU_DATA'!C:C, $A$30)) -> 0 | H30: =IF(OR($A$30="", C30=0), 0, G30/C30) -> 0 | I30: =IF(OR($A$30="", F30=0), 0, E30/F30) -> 0
B31: =IF($A$31="","", SUMIFS('RAW_SKU_DATA'!H:H, 'RAW_SKU_DATA'!A:A, $B$1, 'RAW_SKU_DATA'!C:C, $A$31)) -> 0 | C31: =IF($A$31="","", SUMIFS('RAW_SKU_DATA'!I:I, 'RAW_SKU_DATA'!A:A, $B$1, 'RAW_SKU_DATA'!C:C, $A$31)) -> 0 | D31: =IF(OR($A$31="", B31=0), 0, C31/B31) -> 0 | E31: =IF($A$31="","", SUMIFS('RAW_SKU_DATA'!K:K, 'RAW_SKU_DATA'!A:A, $B$1, 'RAW_SKU_DATA'!C:C, $A$31)) -> 0 | F31: =IF($A$31="","", SUMIFS('RAW_SKU_DATA'!L:L, 'RAW_SKU_DATA'!A:A, $B$1, 'RAW_SKU_DATA'!C:C, $A$31)) -> 0 | G31: =IF($A$31="","", SUMIFS('RAW_SKU_DATA'!M:M, 'RAW_SKU_DATA'!A:A, $B$1, 'RAW_SKU_DATA'!C:C, $A$31)) -> 0 | H31: =IF(OR($A$31="", C31=0), 0, G31/C31) -> 0 | I31: =IF(OR($A$31="", F31=0), 0, E31/F31) -> 0
B32: =IF($A$32="","", SUMIFS('RAW_SKU_DATA'!H:H, 'RAW_SKU_DATA'!A:A, $B$1, 'RAW_SKU_DATA'!C:C, $A$32)) -> 0 | C32: =IF($A$32="","", SUMIFS('RAW_SKU_DATA'!I:I, 'RAW_SKU_DATA'!A:A, $B$1, 'RAW_SKU_DATA'!C:C, $A$32)) -> 0 | D32: =IF(OR($A$32="", B32=0), 0, C32/B32) -> 0 | E32: =IF($A$32="","", SUMIFS('RAW_SKU_DATA'!K:K, 'RAW_SKU_DATA'!A:A, $B$1, 'RAW_SKU_DATA'!C:C, $A$32)) -> 0 | F32: =IF($A$32="","", SUMIFS('RAW_SKU_DATA'!L:L, 'RAW_SKU_DATA'!A:A, $B$1, 'RAW_SKU_DATA'!C:C, $A$32)) -> 0 | G32: =IF($A$32="","", SUMIFS('RAW_SKU_DATA'!M:M, 'RAW_SKU_DATA'!A:A, $B$1, 'RAW_SKU_DATA'!C:C, $A$32)) -> 0 | H32: =IF(OR($A$32="", C32=0), 0, G32/C32) -> 0 | I32: =IF(OR($A$32="", F32=0), 0, E32/F32) -> 0
B33: =IF($A$33="","", SUMIFS('RAW_SKU_DATA'!H:H, 'RAW_SKU_DATA'!A:A, $B$1, 'RAW_SKU_DATA'!C:C, $A$33)) -> 0 | C33: =IF($A$33="","", SUMIFS('RAW_SKU_DATA'!I:I, 'RAW_SKU_DATA'!A:A, $B$1, 'RAW_SKU_DATA'!C:C, $A$33)) -> 0 | D33: =IF(OR($A$33="", B33=0), 0, C33/B33) -> 0 | E33: =IF($A$33="","", SUMIFS('RAW_SKU_DATA'!K:K, 'RAW_SKU_DATA'!A:A, $B$1, 'RAW_SKU_DATA'!C:C, $A$33)) -> 0 | F33: =IF($A$33="","", SUMIFS('RAW_SKU_DATA'!L:L, 'RAW_SKU_DATA'!A:A, $B$1, 'RAW_SKU_DATA'!C:C, $A$33)) -> 0 | G33: =IF($A$33="","", SUMIFS('RAW_SKU_DATA'!M:M, 'RAW_SKU_DATA'!A:A, $B$1, 'RAW_SKU_DATA'!C:C, $A$33)) -> 0 | H33: =IF(OR($A$33="", C33=0), 0, G33/C33) -> 0 | I33: =IF(OR($A$33="", F33=0), 0, E33/F33) -> 0
B34: =IF($A$34="","", SUMIFS('RAW_SKU_DATA'!H:H, 'RAW_SKU_DATA'!A:A, $B$1, 'RAW_SKU_DATA'!C:C, $A$34)) -> 0 | C34: =IF($A$34="","", SUMIFS('RAW_SKU_DATA'!I:I, 'RAW_SKU_DATA'!A:A, $B$1, 'RAW_SKU_DATA'!C:C, $A$34)) -> 0 | D34: =IF(OR($A$34="", B34=0), 0, C34/B34) -> 0 | E34: =IF($A$34="","", SUMIFS('RAW_SKU_DATA'!K:K, 'RAW_SKU_DATA'!A:A, $B$1, 'RAW_SKU_DATA'!C:C, $A$34)) -> 0 | F34: =IF($A$34="","", SUMIFS('RAW_SKU_DATA'!L:L, 'RAW_SKU_DATA'!A:A, $B$1, 'RAW_SKU_DATA'!C:C, $A$34)) -> 0 | G34: =IF($A$34="","", SUMIFS('RAW_SKU_DATA'!M:M, 'RAW_SKU_DATA'!A:A, $B$1, 'RAW_SKU_DATA'!C:C, $A$34)) -> 0 | H34: =IF(OR($A$34="", C34=0), 0, G34/C34) -> 0 | I34: =IF(OR($A$34="", F34=0), 0, E34/F34) -> 0
B35: =IF($A$35="","", SUMIFS('RAW_SKU_DATA'!H:H, 'RAW_SKU_DATA'!A:A, $B$1, 'RAW_SKU_DATA'!C:C, $A$35)) -> 0 | C35: =IF($A$35="","", SUMIFS('RAW_SKU_DATA'!I:I, 'RAW_SKU_DATA'!A:A, $B$1, 'RAW_SKU_DATA'!C:C, $A$35)) -> 0 | D35: =IF(OR($A$35="", B35=0), 0, C35/B35) -> 0 | E35: =IF($A$35="","", SUMIFS('RAW_SKU_DATA'!K:K, 'RAW_SKU_DATA'!A:A, $B$1, 'RAW_SKU_DATA'!C:C, $A$35)) -> 0 | F35: =IF($A$35="","", SUMIFS('RAW_SKU_DATA'!L:L, 'RAW_SKU_DATA'!A:A, $B$1, 'RAW_SKU_DATA'!C:C, $A$35)) -> 0 | G35: =IF($A$35="","", SUMIFS('RAW_SKU_DATA'!M:M, 'RAW_SKU_DATA'!A:A, $B$1, 'RAW_SKU_DATA'!C:C, $A$35)) -> 0 | H35: =IF(OR($A$35="", C35=0), 0, G35/C35) -> 0 | I35: =IF(OR($A$35="", F35=0), 0, E35/F35) -> 0
B36: =IF($A$36="","", SUMIFS('RAW_SKU_DATA'!H:H, 'RAW_SKU_DATA'!A:A, $B$1, 'RAW_SKU_DATA'!C:C, $A$36)) -> 0 | C36: =IF($A$36="","", SUMIFS('RAW_SKU_DATA'!I:I, 'RAW_SKU_DATA'!A:A, $B$1, 'RAW_SKU_DATA'!C:C, $A$36)) -> 0 | D36: =IF(OR($A$36="", B36=0), 0, C36/B36) -> 0 | E36: =IF($A$36="","", SUMIFS('RAW_SKU_DATA'!K:K, 'RAW_SKU_DATA'!A:A, $B$1, 'RAW_SKU_DATA'!C:C, $A$36)) -> 0 | F36: =IF($A$36="","", SUMIFS('RAW_SKU_DATA'!L:L, 'RAW_SKU_DATA'!A:A, $B$1, 'RAW_SKU_DATA'!C:C, $A$36)) -> 0 | G36: =IF($A$36="","", SUMIFS('RAW_SKU_DATA'!M:M, 'RAW_SKU_DATA'!A:A, $B$1, 'RAW_SKU_DATA'!C:C, $A$36)) -> 0 | H36: =IF(OR($A$36="", C36=0), 0, G36/C36) -> 0 | I36: =IF(OR($A$36="", F36=0), 0, E36/F36) -> 0
B37: =IF($A$37="","", SUMIFS('RAW_SKU_DATA'!H:H, 'RAW_SKU_DATA'!A:A, $B$1, 'RAW_SKU_DATA'!C:C, $A$37)) -> 0 | C37: =IF($A$37="","", SUMIFS('RAW_SKU_DATA'!I:I, 'RAW_SKU_DATA'!A:A, $B$1, 'RAW_SKU_DATA'!C:C, $A$37)) -> 0 | D37: =IF(OR($A$37="", B37=0), 0, C37/B37) -> 0 | E37: =IF($A$37="","", SUMIFS('RAW_SKU_DATA'!K:K, 'RAW_SKU_DATA'!A:A, $B$1, 'RAW_SKU_DATA'!C:C, $A$37)) -> 0 | F37: =IF($A$37="","", SUMIFS('RAW_SKU_DATA'!L:L, 'RAW_SKU_DATA'!A:A, $B$1, 'RAW_SKU_DATA'!C:C, $A$37)) -> 0 | G37: =IF($A$37="","", SUMIFS('RAW_SKU_DATA'!M:M, 'RAW_SKU_DATA'!A:A, $B$1, 'RAW_SKU_DATA'!C:C, $A$37)) -> 0 | H37: =IF(OR($A$37="", C37=0), 0, G37/C37) -> 0 | I37: =IF(OR($A$37="", F37=0), 0, E37/F37) -> 0
B38: =IF($A$38="","", SUMIFS('RAW_SKU_DATA'!H:H, 'RAW_SKU_DATA'!A:A, $B$1, 'RAW_SKU_DATA'!C:C, $A$38)) -> 0 | C38: =IF($A$38="","", SUMIFS('RAW_SKU_DATA'!I:I, 'RAW_SKU_DATA'!A:A, $B$1, 'RAW_SKU_DATA'!C:C, $A$38)) -> 0 | D38: =IF(OR($A$38="", B38=0), 0, C38/B38) -> 0 | E38: =IF($A$38="","", SUMIFS('RAW_SKU_DATA'!K:K, 'RAW_SKU_DATA'!A:A, $B$1, 'RAW_SKU_DATA'!C:C, $A$38)) -> 0 | F38: =IF($A$38="","", SUMIFS('RAW_SKU_DATA'!L:L, 'RAW_SKU_DATA'!A:A, $B$1, 'RAW_SKU_DATA'!C:C, $A$38)) -> 0 | G38: =IF($A$38="","", SUMIFS('RAW_SKU_DATA'!M:M, 'RAW_SKU_DATA'!A:A, $B$1, 'RAW_SKU_DATA'!C:C, $A$38)) -> 0 | H38: =IF(OR($A$38="", C38=0), 0, G38/C38) -> 0 | I38: =IF(OR($A$38="", F38=0), 0, E38/F38) -> 0
B39: =IF($A$39="","", SUMIFS('RAW_SKU_DATA'!H:H, 'RAW_SKU_DATA'!A:A, $B$1, 'RAW_SKU_DATA'!C:C, $A$39)) -> 0 | C39: =IF($A$39="","", SUMIFS('RAW_SKU_DATA'!I:I, 'RAW_SKU_DATA'!A:A, $B$1, 'RAW_SKU_DATA'!C:C, $A$39)) -> 0 | D39: =IF(OR($A$39="", B39=0), 0, C39/B39) -> 0 | E39: =IF($A$39="","", SUMIFS('RAW_SKU_DATA'!K:K, 'RAW_SKU_DATA'!A:A, $B$1, 'RAW_SKU_DATA'!C:C, $A$39)) -> 0 | F39: =IF($A$39="","", SUMIFS('RAW_SKU_DATA'!L:L, 'RAW_SKU_DATA'!A:A, $B$1, 'RAW_SKU_DATA'!C:C, $A$39)) -> 0 | G39: =IF($A$39="","", SUMIFS('RAW_SKU_DATA'!M:M, 'RAW_SKU_DATA'!A:A, $B$1, 'RAW_SKU_DATA'!C:C, $A$39)) -> 0 | H39: =IF(OR($A$39="", C39=0), 0, G39/C39) -> 0 | I39: =IF(OR($A$39="", F39=0), 0, E39/F39) -> 0
B40: =IF($A$40="","", SUMIFS('RAW_SKU_DATA'!H:H, 'RAW_SKU_DATA'!A:A, $B$1, 'RAW_SKU_DATA'!C:C, $A$40)) -> 0 | C40: =IF($A$40="","", SUMIFS('RAW_SKU_DATA'!I:I, 'RAW_SKU_DATA'!A:A, $B$1, 'RAW_SKU_DATA'!C:C, $A$40)) -> 0 | D40: =IF(OR($A$40="", B40=0), 0, C40/B40) -> 0 | E40: =IF($A$40="","", SUMIFS('RAW_SKU_DATA'!K:K, 'RAW_SKU_DATA'!A:A, $B$1, 'RAW_SKU_DATA'!C:C, $A$40)) -> 0 | F40: =IF($A$40="","", SUMIFS('RAW_SKU_DATA'!L:L, 'RAW_SKU_DATA'!A:A, $B$1, 'RAW_SKU_DATA'!C:C, $A$40)) -> 0 | G40: =IF($A$40="","", SUMIFS('RAW_SKU_DATA'!M:M, 'RAW_SKU_DATA'!A:A, $B$1, 'RAW_SKU_DATA'!C:C, $A$40)) -> 0 | H40: =IF(OR($A$40="", C40=0), 0, G40/C40) -> 0 | I40: =IF(OR($A$40="", F40=0), 0, E40/F40) -> 0
B41: =IF($A$41="","", SUMIFS('RAW_SKU_DATA'!H:H, 'RAW_SKU_DATA'!A:A, $B$1, 'RAW_SKU_DATA'!C:C, $A$41)) -> 0 | C41: =IF($A$41="","", SUMIFS('RAW_SKU_DATA'!I:I, 'RAW_SKU_DATA'!A:A, $B$1, 'RAW_SKU_DATA'!C:C, $A$41)) -> 0 | D41: =IF(OR($A$41="", B41=0), 0, C41/B41) -> 0 | E41: =IF($A$41="","", SUMIFS('RAW_SKU_DATA'!K:K, 'RAW_SKU_DATA'!A:A, $B$1, 'RAW_SKU_DATA'!C:C, $A$41)) -> 0 | F41: =IF($A$41="","", SUMIFS('RAW_SKU_DATA'!L:L, 'RAW_SKU_DATA'!A:A, $B$1, 'RAW_SKU_DATA'!C:C, $A$41)) -> 0 | G41: =IF($A$41="","", SUMIFS('RAW_SKU_DATA'!M:M, 'RAW_SKU_DATA'!A:A, $B$1, 'RAW_SKU_DATA'!C:C, $A$41)) -> 0 | H41: =IF(OR($A$41="", C41=0), 0, G41/C41) -> 0 | I41: =IF(OR($A$41="", F41=0), 0, E41/F41) -> 0
...
